Exception ignored in: Exception in thread <function _ConnectionBase.__del__ at 0x000002433CC735B0>QueueFeederThread
:
Traceback (most recent call last):
Traceback (most recent call last):
  File "c:\tools\Anaconda3\envs\torch2_cuda11.8\lib\multiprocessing\connection.py", line 132, in __del__
  File "c:\tools\Anaconda3\envs\torch2_cuda11.8\lib\multiprocessing\queues.py", line 239, in _feed
        self._close()reader_close()
  File "c:\tools\Anaconda3\envs\torch2_cuda11.8\lib\multiprocessing\connection.py", line 277, in _close
  File "c:\tools\Anaconda3\envs\torch2_cuda11.8\lib\multiprocessing\connection.py", line 177, in close
        _CloseHandle(self._handle)self._close()
OSError  File "c:\tools\Anaconda3\envs\torch2_cuda11.8\lib\multiprocessing\connection.py", line 277, in _close
: [WinError 6] The handle is invalid
    _CloseHandle(self._handle)
OSError: [WinError 6] The handle is invalid
During handling of the above exception, another exception occurred:
Traceback (most recent call last):
  File "c:\tools\Anaconda3\envs\torch2_cuda11.8\lib\threading.py", line 1016, in _bootstrap_inner
    self.run()
  File "c:\tools\Anaconda3\envs\torch2_cuda11.8\lib\threading.py", line 953, in run
    self._target(*self._args, **self._kwargs)
  File "c:\tools\Anaconda3\envs\torch2_cuda11.8\lib\multiprocessing\queues.py", line 271, in _feed
    queue_sem.release()
ValueError: semaphore or lock released too many times
Using device: cuda
Total number of examples in dataset: 82810.
Total number of examples used: 4140.
Number of training examples: 3312. Number of training batches: 104.
Number of validation examples: 828. Number of validation batches: 26.
Number of test examples: 414. Number of test batches: 13.